Workbook

Sheet Attekintes
A1: Bander - Frontend manuális, E2E teszt dokumentáció
A3: Projekt | B3: Bander
A4: Dokumentum típusa | B4: Frontend manuális, E2E tesztesetek
A5: Hatókör | B5: Csak frontend képernyők és UI folyamatok
A7: Összesítés | D7: Modulok
A8: Összes teszteset | B8: =COUNTA(Tesztesetek!A:A)-1 -> 90 | D8: Nyitóoldal | E8: Publikus landing oldal, előnézeti listák, CTA-k
A9: Magas prioritás | B9: =COUNTIF(Tesztesetek!H:H,"Magas") -> 40 | D9: Bejelentkezés | E9: Login űrlap és navigáció
A10: Közepes prioritás | B10: =COUNTIF(Tesztesetek!H:H,"Közepes") -> 43 | D10: Regisztráció | E10: Sign up űrlap és validáció
A11: Alacsony prioritás | B11: =COUNTIF(Tesztesetek!H:H,"Alacsony") -> 7 | D11: Artist kereső | E11: Artist lista, kereső és szűrők
A12: Validációs tesztek | B12: =COUNTIF(Tesztesetek!D:D,"Validáció") -> 8 | D12: Artist profil | E12: Artist részletes oldal, üzenetküldés, referral linkek
A13: Navigációs tesztek | B13: =COUNTIF(Tesztesetek!D:D,"Navigáció")+COUNTIF(Tesztesetek!D:D,"UI/Navigáció") -> 7 | D13: Artist profil szerkesztés | E13: Saját artist profil adatainak módosítása
A14: UI checklist elemek | B14: =COUNTA(UI_ellenorzes!A:A)-1 -> 20 | D14: Üzenetek | E14: Chat/beszélgetés nézet
A15: Jogosultsági esetek | B15: =COUNTA(Jogosultsagok!A:A)-1 -> 18 | D15: Band kereső | E15: Band lista, kereső és szűrők
D16: Band profil | E16: Band részletes oldal, application űrlap, események, tagok
D17: Band kezelő oldal | E17: Band adatok és új esemény létrehozása
D18: About | E18: Projekt leírás és ÁSZF letöltés
D19: Admin | E19: Report dashboard és moderációs műveletek
D20: Globális navigáció | E20: Fejléc, állapotfüggő menüelemek

Sheet Tesztesetek
A1: TC_ID | B1: Modul | C1: Oldal/Funkció | D1: Teszt típusa | E1: Előfeltétel | F1: Tesztlépések | G1: Elvárt eredmény | H1: Prioritás | I1: E2E | J1: Manuális | K1: Megjegyzés | M1: Jelmagyarázat
A2: TC-FE-001 | B2: Nyitóoldal | C2: Publikus kezdőlap | D2: Funkcionális | E2: Publikus felhasználó | F2: Nyisd meg a kezdőlapot. | G2: A Bander nyitóoldal betölt, a főcím, rövid leírás és a fő CTA látható. | H2: Magas | I2: Sikeres | J2: Sikeres | M2: Funkcionális | N2: Alap működési ellenőrzés
A3: TC-FE-002 | B3: Nyitóoldal | C3: Felső navigáció | D3: UI/Navigáció | E3: Publikus felhasználó | F3: Ellenőrizd a fejlécet. | G3: A Bands / Artists / Events / Log in menüpontok megjelennek és kattinthatók. | H3: Magas | I3: Sikeres | J3: Sikeres | M3: Validáció | N3: Űrlap és input ellenőrzés
A4: TC-FE-003 | B4: Nyitóoldal | C4: Új előadók blokk | D4: Funkcionális | E4: Publikus felhasználó | F4: Görgess az 'New Artists' szekcióhoz. | G4: Legalább több artist kártya jelenik meg névvel és rövid leírással az artists-grid-ben. | H4: Közepes | I4: Sikeres | J4: Sikeres | M4: Navigáció | N4: Oldalak közötti átmenet
A5: TC-FE-004 | B5: Nyitóoldal | C5: Bandák előnézete | D5: Funkcionális | E5: Publikus felhasználó | F5: Ellenőrizd a Bands szekciót. | G5: A band kártyák megjelennek névvel és keresett szereppel/leírással. | H5: Közepes | I5: Sikeres | J5: Sikeres | M5: UI | N5: Megjelenés, layout, olvashatóság
A6: TC-FE-005 | B6: Nyitóoldal | C6: Események előnézete | D6: Funkcionális | E6: Publikus felhasználó | F6: Ellenőrizd az Upcoming events blokkot. | G6: Az eseménykártyák megjelennek zenekarnévvel, eseménynévvel, dátummal és 'See more' linkkel. | H6: Közepes | I6: Sikeres | J6: Sikeres
A7: TC-FE-006 | B7: Nyitóoldal | C7: CTA a teljes funkciókhoz | D7: Funkcionális | E7: Publikus felhasználó | F7: Görgess a 'For all features' részhez. | G7: A Log in és Sign up CTA gombok láthatók és egyértelműek. | H7: Közepes | I7: Sikeres | J7: Sikeres
A8: TC-FE-007 | B8: Bejelentkezés | C8: Login oldal betöltése | D8: Funkcionális | E8: Publikus felhasználó | F8: Nyisd meg a Log in oldalt. | G8: Az email és password mező, a Log in gomb, az 'or' elválasztó és a Get started CTA látható. | H8: Magas | I8: Sikeres | J8: Sikeres
A9: TC-FE-008 | B9: Bejelentkezés | C9: Kötelező mezők ellenőrzése | D9: Validáció | E9: Publikus felhasználó | F9: Hagyd üresen az űrlapot és küldd el. | G9: A frontend jelzi, hogy az email és a jelszó kötelező. | H9: Magas | I9: Sikeres | J9: Sikeres
A10: TC-FE-009 | B10: Bejelentkezés | C10: Hibás hitelesítő adatok kezelése | D10: Validáció | E10: Publikus felhasználó | F10: Adj meg hibás email/jelszó párost és kattints a Log in gombra. | G10: Felhasználóbarát hibaüzenet jelenik meg, az oldal nem omlik össze. | H10: Magas | I10: Sikeres | J10: Sikeres
A11: TC-FE-010 | B11: Bejelentkezés | C11: Sikeres bejelentkezés UI folyamata | D11: Funkcionális | E11: Érvényes felhasználó | F11: Adj meg érvényes adatokat és jelentkezz be. | G11: A felhasználó bejelentkezett állapotba kerül, és a fejléc / oldal tartalma ennek megfelelően változik. | H11: Magas | I11: Sikeres | J11: Sikeres
A12: TC-FE-011 | B12: Bejelentkezés | C12: Get started navigáció | D12: Navigáció | E12: Publikus felhasználó | F12: Kattints a Get started elemre. | G12: A rendszer a regisztrációs oldalra vagy a regisztrációs folyamatra visz. | H12: Közepes | I12: Sikeres | J12: Sikeres
A13: TC-FE-012 | B13: Regisztráció | C13: Sign up oldal betöltése | D13: Funkcionális | E13: Publikus felhasználó | F13: Nyisd meg a Sign up oldalt. | G13: Az email, jelszó, jelszó megerősítés mezők és a Sign Up gomb megjelennek. | H13: Magas | I13: Sikeres | J13: Sikeres
A14: TC-FE-013 | B14: Regisztráció | C14: Kötelező mezők ellenőrzése | D14: Validáció | E14: Publikus felhasználó | F14: Hagyd üresen a mezőket és küldd el az űrlapot. | G14: A frontend kiemeli a kötelező mezőket. | H14: Magas | I14: Sikeres | J14: Sikeres
A15: TC-FE-014 | B15: Regisztráció | C15: Jelszó megerősítés egyezése | D15: Validáció | E15: Publikus felhasználó | F15: Adj meg eltérő jelszavakat. | G15: A rendszer jelzi, hogy a két jelszó nem egyezik. | H15: Magas | I15: Sikeres | J15: Sikeres
A16: TC-FE-015 | B16: Regisztráció | C16: Sikeres regisztráció UI folyamata | D16: Funkcionális | E16: Új email cím | F16: Töltsd ki helyesen az űrlapot és küldd el. | G16: Sikeres visszajelzés vagy továbblépés jelenik meg, a felhasználó a következő logikus oldalra jut. | H16: Magas | I16: Sikeres | J16: Sikeres
A17: TC-FE-016 | B17: Artist kereső | C17: Artists lista betöltése | D17: Funkcionális | E17: Bejelentkezett felhasználó | F17: Jelentkezz be, majd nyisd meg az /artists oldalt. | G17: Az artist-grid megjelenik legalább 1 artist-card-dal. | H17: Magas | I17: Sikeres | J17: Sikeres
... A37: TC-FE-036 | B37: Band kereső | C37: Szöveges kereső működése | D37: Funkcionális | E37: Bejelentkezett felhasználó, Band lista betöltve | F37: Írj be keresőszót a .band-search input mezőbe. | G37: A találatok csak a megadott hangszert kereső bandákat mutatják. | H37: Magas | I37: Sikeres | J37: Sikeres
A38: TC-FE-037 | B38: Band kereső | C38: Szűrés műfaj alapján | D38: Funkcionális | E38: Band lista betöltve | F38: Válassz Genre(s) szűrőt. | G38: A lista a kiválasztott műfajhoz illő bandákra szűkül. | H38: Közepes | I38: Nem releváns | J38: Sikeres | K38: Nincs implementálva E2E tesztben - a Band keresőben csak város szűrő van, műfaj szűrő nem elérhető.
A39: TC-FE-038 | B39: Band kereső | C39: Üres találati állapot | D39: UI/Funkcionális | E39: Bejelentkezett felhasználó, Band lista betöltve | F39: Írj be nem létező keresőszót (pl. 'xyznonexistent12345'). | G39: Nincs .band-card a listában (0 találat). | H39: Közepes | I39: Sikeres | J39: Sikeres
A40: TC-FE-039 | B40: Band profil | C40: Band adatlap megjelenítése | D40: Funkcionális | E40: Bejelentkezett felhasználó, Band profil megnyitva | F40: Jelentkezz be, navigálj a /bands oldalra, kattints az első .band-card-ra. | G40: A .band-profile-page megjelenik, a .band-info-text tartalmazza az Open spots szöveget, és a Current members szekció látható. | H40: Magas | I40: Sikeres | J40: Sikeres
A41: TC-FE-040 | B41: Band profil | C41: Band csatlakozási információ | D41: Funkcionális | E41: Band részletes oldal megnyitva | F41: Ellenőrizd a .band-apply szekciót. | G41: A .band-apply tartalmazza a 'Csatlakozás' szöveget és az útmutatást a tagokkal való kapcsolatfelvételhez. | H41: Közepes | I41: Sikeres | J41: Sikeres
A42: TC-FE-041 | B42: Band profil | C42: Report band gomb | D42: Funkcionális | E42: Band jelentkezési űrlap megnyitva | F42: Kattints a .band-report-btn gombra. | G42: A .report-modal megjelenik a jelentési űrlappal. | H42: Magas | I42: Sikeres | J42: Sikeres
A43: TC-FE-042 | B43: Band profil | C43: Current members blokk | D43: UI/Funkcionális | E43: Érvényes jelentkezési adatok | F43: Görgess a 'Current members' szekcióhoz. | G43: A .band-members szekció megjelenik. | H43: Magas | I43: Sikeres | J43: Sikeres
A44: TC-FE-043 | B44: Band profil | C44: Events blokk | D44: UI/Funkcionális | E44: Band részletes oldal megnyitva | F44: Ellenőrizd a .band-events szekciót. | G44: Legalább 1 .event-card megjelenik a .band-events-en belül. | H44: Közepes | I44: Sikeres | J44: Sikeres
A45: TC-FE-044 | B45: Band profil | C45: Upcoming events blokk | D45: UI/Funkcionális | E45: Band részletes oldal megnyitva | F45: Ellenőrizd az Upcoming events szekciót. | G45: Az eseménykártyák bandnévvel, eseménynévvel, dátummal és leírással jelennek meg. | H45: Közepes | I45: Nem releváns | J45: Sikeres | K45: TC-FE-043 lefedi az events blokkot. Ez a teszteset redundáns.
A46: TC-FE-045 | B46: Band kezelő oldal | C46: Band szerkesztő űrlap előtöltése | D46: Funkcionális | E46: Bejelentkezett band admin / tulajdonos | F46: Jelentkezz be, kattints a 'Manage band' linkre a navbar-ben. | G46: A név, contact info, email és members mezők előtöltve jelennek meg. | H46: Magas | I46: Sikeres | J46: Sikeres
A47: TC-FE-046 | B47: Band kezelő oldal | C47: Band adatok mentése | D47: Funkcionális | E47: Érvényes módosítások | F47: Módosítsd a band nevet az első .form-col .field input-ban, majd kattints a 'Save changes' gombra. | G47: A .toast elem megjelenik a sikeres mentés visszajelzésével. | H47: Magas | I47: Sikeres | J47: Sikeres
A48: TC-FE-047 | B48: Band kezelő oldal | C48: Új esemény űrlap mezői | D48: Funkcionális | E48: Band kezelő oldal megnyitva | F48: Ellenőrizd a második .form-col (New Event) szekciót. | G48: A select (post_type), textarea (message) és input[type=date] (expires_at) mezők megjelennek. | H48: Közepes | I48: Sikeres | J48: Sikeres
A49: TC-FE-048 | B49: Band kezelő oldal | C49: Új esemény validációja | D49: Validáció | E49: New Event űrlap megnyitva | F49: A második .form-col-ban kattints a 'Create event' gombra anélkül, hogy kitöltöd a mezőket. | G49: A 'required' hibaüzenet jelenik meg. | H49: Magas | I49: Sikeres | J49: Sikeres
A50: TC-FE-049 | B50: Band kezelő oldal | C50: Új esemény létrehozása | D50: Funkcionális | E50: Érvényes esemény adatok | F50: Töltsd ki az expires_at (2030-01-01) és a message (textarea) mezőket, majd kattints a 'Create event' gombra. | G50: A .toast 'Event created' üzenetet jelenít meg. | H50: Magas | I50: Sikeres | J50: Sikeres
A51: TC-FE-050 | B51: About | C51: About oldal tartalma | D51: Funkcionális | E51: Publikus vagy bejelentkezett felhasználó | F51: Nyisd meg az About Bander oldalt. | G51: A leíró szöveg és a Terms and Conditions letöltési lehetőség látható. | H51: Közepes | I51: Sikeres | J51: Sikeres
A52: TC-FE-051 | B52: About | C52: Terms and Conditions CTA | D52: Navigáció | E52: About oldal megnyitva | F52: Kattints a letöltési lehetőségre. | G52: A letöltés vagy a dokumentum megnyitása elindul. | H52: Alacsony | I52: Sikeres | J52: Sikeres
A53: TC-FE-052 | B53: Admin | C53: Admin dashboard betöltése | D53: Funkcionális | E53: Admin jogosultságú felhasználó | F53: Nyisd meg az admin oldalt. | G53: A Users / Bands / Reports / Events összesítő számok láthatók. | H53: Magas | I53: Sikeres | J53: Sikeres
A54: TC-FE-053 | B54: Admin | C54: Reports tábla megjelenítése | D54: Funkcionális | E54: Admin oldal megnyitva | F54: Ellenőrizd a report táblázatot. | G54: Az ID, Reporter, Subject, Status th fejlécek megjelennek az .adm-main-en belül. | H54: Magas | I54: Sikeres | J54: Sikeres
A55: TC-FE-054 | B55: Admin | C55: Felhasználó tiltás UI | D55: Funkcionális | E55: Admin oldal megnyitva | F55: Kattints a 'Manual Actions' fülre (.adm-tabs), majd az .adm-actions-grid első .adm-card-jában töltsd ki a UserID .adm-input mezőt és kattints a 'Ban User' gombra. | G55: A művelethez tartozó visszajelzés / megerősítés látható. | H55: Közepes | I55: Sikeres | J55: Sikeres
A56: TC-FE-055 | B56: Admin | C56: Band tiltás UI | D56: Funkcionális | E56: Admin oldal megnyitva | F56: A 'Manual Actions' fülön az .adm-actions-grid második .adm-card-jában töltsd ki a BandID és Reason .adm-input mezőket, majd kattints a 'Ban Band' gombra. | G56: A művelethez tartozó visszajelzés / megerősítés látható. | H56: Közepes | I56: Sikeres | J56: Sikeres
A57: TC-FE-056 | B57: Admin | C57: Esemény törlés UI | D57: Funkcionális | E57: Admin oldal megnyitva | F57: A 'Manual Actions' fülön az .adm-actions-grid harmadik .adm-card-jában töltsd ki az EventID és Reason .adm-input mezőket, majd kattints a 'Delete Event' gombra. | G57: A törléshez tartozó alert visszajelzés megjelenik. | H57: Közepes | I57: Sikeres | J57: Sikeres
... A73: TC-FE-072 | B73: Artist profil szerkesztés | C73: Profilkép feltöltés | D73: Funkcionális | E73: Bejelentkezett felhasználó, Profil szerkesztő oldal megnyitva | F73: A 'Profile picture' ImageUploadField-ben válassz fájlt. | G73: Az előnézeti kép megjelenik, a feltöltés a szerverre megtörténik. | H73: Közepes | I73: Sikeres | J73: Sikeres
A74: TC-FE-073 | B74: Bejelentkezés | C74: Signup és bejelentkezés folyamata | D74: Funkcionális | E74: Új email cím | F74: Regisztrálj új fiókot, majd navigálj az /artists oldalra és kattints az első artist kártyára. | G74: A regisztráció sikeres, az artist profil oldal betölt. A teszt után a létrehozott felhasználó törlésre kerül (cleanup). | H74: Magas | I74: Nem releváns | J74: Sikeres | K74: Signup->artists->card flow + cleanup
...

Sheet UI_ellenorzes
A1: UI_ID | B1: Oldal | C1: Elem | D1: Ellenőrzési szempont | E1: E2E | F1: Manuális | G1: Megjegyzés
A2: UI-001 | B2: Nyitóoldal | C2: Hero szekció | D2: A címsor, alcím és CTA vizuálisan elkülönül, jól olvasható. | E2: Sikeres | F2: Sikeres
A3: UI-002 | B3: Nyitóoldal | C3: Kártyák | D3: Az artist / band / event kártyák egységes méretűek és tördelésűek. | E3: Sikeres | F3: Sikeres
A4: UI-003 | B4: Bejelentkezés | C4: Űrlap mezők | D4: A mezők címkéi olvashatók, fókuszállapot egyértelmű. | E4: Sikeres | F4: Sikeres
A5: UI-004 | B5: Regisztráció | C5: Űrlap elrendezés | D5: A mezők és a CTA között megfelelő térköz van. | E5: Sikeres | F5: Sikeres
A6: UI-005 | B6: Artist kereső | C6: Szűrősáv | D6: A szűrők logikus sorrendben jelennek meg, könnyen módosíthatók. | E6: Sikeres | F6: Sikeres
A7: UI-006 | B7: Artist profil | C7: Profil blokk | D7: Kép, név és metaadatok jól csoportosítottak. | E7: Sikeres | F7: Sikeres
A8: UI-007 | B8: Artist profil | C8: Leírás blokk | D8: A hosszabb szöveg nem lóg ki és mobilon is olvasható. | E8: Sikeres | F8: Sikeres
A9: UI-008 | B9: Üzenetek | C9: Chat felület | D9: Az üzenetlista és az input elkülönül, görgetés működik. | E9: Sikeres | F9: Sikeres
A10: UI-009 | B10: Band kereső | C10: Kártyarács | D10: A kártyák egyenletesen rendezettek, nem csúsznak egymásra. | E10: Sikeres | F10: Sikeres
A11: UI-010 | B11: Band profil | C11: Csatlakozási szekció | D11: A band leírás és a csatlakozási információ (.band-apply) jól elkülönül. A Report gomb működik. | E11: Sikeres | F11: Sikeres
A12: UI-011 | B12: Band kezelő oldal | C12: Űrlap + új esemény blokk | D12: A két funkcionális blokk vizuálisan elkülönül. | E12: Sikeres | F12: Sikeres
A13: UI-012 | B13: About | C13: Szöveges oldal | D13: A hosszú szöveg megfelelő sortávval, jól olvashatóan jelenik meg. | E13: Sikeres | F13: Sikeres
... A21: UI-020 | B21: Admin | C21: Status pill-ek | D21: A report státusz pill-ek (Open/Reviewing/Resolved) különböző színűek és megkülönböztethetők. | E21: Sikeres | F21: Sikeres

Sheet Jogosultsagok
A1: AUTH_ID | B1: Szerepkör | C1: Oldal/Funkció | D1: Elvárt hozzáférés | E1: Megjegyzés | F1: Manuális | G1: E2E | H1: Teszt eredmény
A2: AUTH-001 | B2: Vendég | C2: Nyitóoldal | D2: Elérhető | E2: A publikus landing oldal megtekinthető bejelentkezés nélkül. | F2: Sikeres | G2: Sikeres
A3: AUTH-002 | B3: Vendég | C3: Artist kereső | D3: Tiltott / redirect (login szükséges) | E3: A /artists oldal bejelentkezés nélkül /login-ra irányít (ProtectedRoute). | F3: Sikeres | G3: Sikeres
A4: AUTH-003 | B4: Vendég | C4: Band kereső | D4: Tiltott / redirect (login szükséges) | E4: A /bands oldal bejelentkezés nélkül /login-ra irányít (ProtectedRoute). | F4: Sikeres | G4: Sikeres
A5: AUTH-004 | B5: Vendég | C5: Artist profil szerkesztés | D5: Tiltott / redirect | E5: A saját profil szerkesztése csak bejelentkezés után érhető el. | F5: Sikeres | G5: Sikeres
A6: AUTH-005 | B6: Vendég | C6: Üzenetek | D6: Tiltott / redirect | E6: Az üzenetküldő felület csak bejelentkezés után érhető el. | F6: Sikeres | G6: Sikeres
A7: AUTH-006 | B7: Vendég | C7: Band kezelő oldal | D7: Tiltott / redirect | E7: Band admin funkciók nem érhetők el publikus felhasználóként. | F7: Sikeres | G7: Sikeres
A8: AUTH-007 | B8: Vendég | C8: Admin | D8: Tiltott / redirect | E8: Az admin felület vendégként nem érhető el. | F8: Sikeres | G8: Sikeres
A9: AUTH-008 | B9: Bejelentkezett user | C9: Artist profil | D9: Elérhető | E9: A részletes profilnézet és message CTA elérhető. | F9: Sikeres | G9: Sikeres
A10: AUTH-009 | B10: Bejelentkezett user | C10: Artist profil szerkesztés | D10: Elérhető (saját profil) | E10: A saját profil szerkesztő űrlapja elérhető. | F10: Sikeres | G10: Sikeres
A11: AUTH-010 | B11: Bejelentkezett user | C11: Üzenetek | D11: Elérhető | E11: Az üzenetküldő oldal használható. | F11: Sikeres | G11: Sikeres
A12: AUTH-011 | B12: Bejelentkezett user | C12: Band jelentkezés | D12: Elérhető | E12: A band application űrlap használható. | F12: Sikeres | G12: Sikeres
A13: AUTH-012 | B13: Bejelentkezett user | C13: Admin | D13: Tiltott / redirect | E13: A normál user nem láthat admin funkciót. | F13: Sikeres | G13: Sikeres
... A19: AUTH-018 | B19: Bejelentkezett user | C19: Band létrehozás | D19: Elérhető | E19: A /bands/create oldal elérhető, ha a felhasználónak nincs bandja. | F19: Sikeres | G19: Sikeres

Sheet Funkcio_matrix
A1: Modul | B1: Képernyő/Folyamat | C1: Lefedett tesztek száma
A2: Nyitóoldal | B2: Publikus landing oldal, előnézeti listák, CTA-k | C2: =COUNTIF(Tesztesetek!B:B,A2) -> 7
A3: Bejelentkezés | B3: Login űrlap és navigáció | C3: =COUNTIF(Tesztesetek!B:B,A3) -> 8
A4: Regisztráció | B4: Sign up űrlap és validáció | C4: =COUNTIF(Tesztesetek!B:B,A4) -> 5
A5: Artist kereső | B5: Artist lista, kereső és szűrők | C5: =COUNTIF(Tesztesetek!B:B,A5) -> 10
A6: Artist profil | B6: Artist részletes oldal, üzenetküldés, referral linkek | C6: =COUNTIF(Tesztesetek!B:B,A6) -> 5
A7: Artist profil szerkesztés | B7: Saját artist profil adatainak módosítása | C7: =COUNTIF(Tesztesetek!B:B,A7) -> 6
A8: Üzenetek | B8: Chat/beszélgetés nézet | C8: =COUNTIF(Tesztesetek!B:B,A8) -> 3
A9: Band kereső | B9: Band lista, kereső és szűrők | C9: =COUNTIF(Tesztesetek!B:B,A9) -> 7
A10: Band profil | B10: Band részletes oldal, application űrlap, események, tagok | C10: =COUNTIF(Tesztesetek!B:B,A10) -> 7
A11: Band kezelő oldal | B11: Band adatok és új esemény létrehozása | C11: =COUNTIF(Tesztesetek!B:B,A11) -> 9
A12: About | B12: Projekt leírás és ÁSZF letöltés | C12: =COUNTIF(Tesztesetek!B:B,A12) -> 3
A13: Admin | B13: Report dashboard és moderációs műveletek | C13: =COUNTIF(Tesztesetek!B:B,A13) -> 10
... A17: Reszponzivitás | B17: Mobil nézet, viewport tesztelés | C17: =COUNTIF(Tesztesetek!B:B,A17) -> 1
